[2025-06-19T10:10:23.743+0000] {local_task_job_runner.py:123} INFO - ::group::Pre task execution logs
[2025-06-19T10:10:23.766+0000] {taskinstance.py:2614} INFO - Dependencies all met for dep_context=non-requeueable deps ti=<TaskInstance: git_clone_and_scp_hello_world.scp_to_hpc manual__2025-06-19T10:10:16.769141+00:00 [queued]>
[2025-06-19T10:10:23.778+0000] {taskinstance.py:2614} INFO - Dependencies all met for dep_context=requeueable deps ti=<TaskInstance: git_clone_and_scp_hello_world.scp_to_hpc manual__2025-06-19T10:10:16.769141+00:00 [queued]>
[2025-06-19T10:10:23.779+0000] {taskinstance.py:2867} INFO - Starting attempt 1 of 1
[2025-06-19T10:10:23.795+0000] {taskinstance.py:2890} INFO - Executing <Task(SFTPOperator): scp_to_hpc> on 2025-06-19 10:10:16.769141+00:00
[2025-06-19T10:10:23.805+0000] {warnings.py:112} WARNING - /home/***/.local/lib/python3.12/site-packages/***/task/task_runner/standard_task_runner.py:70: DeprecationWarning: This process (pid=1412) is multi-threaded, use of fork() may lead to deadlocks in the child.
  pid = os.fork()

[2025-06-19T10:10:23.808+0000] {standard_task_runner.py:72} INFO - Started process 1419 to run task
[2025-06-19T10:10:23.810+0000] {standard_task_runner.py:104} INFO - Running: ['***', 'tasks', 'run', 'git_clone_and_scp_hello_world', 'scp_to_hpc', 'manual__2025-06-19T10:10:16.769141+00:00', '--job-id', '343', '--raw', '--subdir', 'DAGS_FOLDER/test.py', '--cfg-path', '/tmp/tmp4a2r5412']
[2025-06-19T10:10:23.816+0000] {standard_task_runner.py:105} INFO - Job 343: Subtask scp_to_hpc
[2025-06-19T10:10:23.875+0000] {task_command.py:467} INFO - Running <TaskInstance: git_clone_and_scp_hello_world.scp_to_hpc manual__2025-06-19T10:10:16.769141+00:00 [running]> on host 9406efa7f156
[2025-06-19T10:10:23.967+0000] {taskinstance.py:3134} INFO - Exporting env vars: AIRFLOW_CTX_DAG_OWNER='***' AIRFLOW_CTX_DAG_ID='git_clone_and_scp_hello_world' AIRFLOW_CTX_TASK_ID='scp_to_hpc' AIRFLOW_CTX_EXECUTION_DATE='2025-06-19T10:10:16.769141+00:00' AIRFLOW_CTX_TRY_NUMBER='1' AIRFLOW_CTX_DAG_RUN_ID='manual__2025-06-19T10:10:16.769141+00:00'
[2025-06-19T10:10:23.969+0000] {logging_mixin.py:190} INFO - Task instance is in running state
[2025-06-19T10:10:23.969+0000] {logging_mixin.py:190} INFO -  Previous state of the Task instance: queued
[2025-06-19T10:10:23.970+0000] {logging_mixin.py:190} INFO - Current task name:scp_to_hpc state:running start_date:2025-06-19 10:10:23.767487+00:00
[2025-06-19T10:10:23.971+0000] {logging_mixin.py:190} INFO - Dag name:git_clone_and_scp_hello_world and current dag run status:running
[2025-06-19T10:10:23.972+0000] {taskinstance.py:732} INFO - ::endgroup::
[2025-06-19T10:10:23.973+0000] {sftp.py:133} INFO - sftp_hook not provided or invalid. Trying ssh_conn_id to create SFTPHook.
[2025-06-19T10:10:23.985+0000] {base.py:84} INFO - Retrieving connection 'hpc_ssh'
[2025-06-19T10:10:23.986+0000] {ssh.py:286} WARNING - No Host Key Verification. This won't protect against Man-In-The-Middle attacks
[2025-06-19T10:10:24.043+0000] {transport.py:1944} INFO - Connected (version 2.0, client OpenSSH_8.0)
[2025-06-19T10:10:24.646+0000] {transport.py:1944} INFO - Authentication (password) successful!
[2025-06-19T10:10:26.361+0000] {sftp.py:169} INFO - [chan 0] Opened sftp connection (server version 3)
[2025-06-19T10:10:26.409+0000] {sftp.py:160} INFO - Starting to transfer file from /tmp/hello-world to .
[2025-06-19T10:10:26.420+0000] {taskinstance.py:3313} ERROR - Task failed with exception
Traceback (most recent call last):
  File "/home/airflow/.local/lib/python3.12/site-packages/airflow/providers/sftp/operators/sftp.py", line 161, in execute
    self.sftp_hook.store_file(_remote_filepath, _local_filepath, confirm=self.confirm)
  File "/home/airflow/.local/lib/python3.12/site-packages/airflow/providers/sftp/hooks/sftp.py", line 246, in store_file
    conn.put(local_full_path, remote_full_path, confirm=confirm)
  File "/home/airflow/.local/lib/python3.12/site-packages/paramiko/sftp_client.py", line 757, in put
    file_size = os.stat(localpath).st_size
                ^^^^^^^^^^^^^^^^^^
FileNotFoundError: [Errno 2] No such file or directory: '/tmp/hello-world'

During handling of the above exception, another exception occurred:

Traceback (most recent call last):
  File "/home/airflow/.local/lib/python3.12/site-packages/airflow/models/taskinstance.py", line 768, in _execute_task
    result = _execute_callable(context=context, **execute_callable_kwargs)
             ^^^^^^^^^^^^^^^^^^^^^^^^^^^^^^^^^^^^^^^^^^^^^^^^^^^^^^^^^^^^^
  File "/home/airflow/.local/lib/python3.12/site-packages/airflow/models/taskinstance.py", line 734, in _execute_callable
    return ExecutionCallableRunner(
           ^^^^^^^^^^^^^^^^^^^^^^^^
  File "/home/airflow/.local/lib/python3.12/site-packages/airflow/utils/operator_helpers.py", line 252, in run
    return self.func(*args, **kwargs)
           ^^^^^^^^^^^^^^^^^^^^^^^^^^
  File "/home/airflow/.local/lib/python3.12/site-packages/airflow/models/baseoperator.py", line 424, in wrapper
    return func(self, *args, **kwargs)
           ^^^^^^^^^^^^^^^^^^^^^^^^^^^
  File "/home/airflow/.local/lib/python3.12/site-packages/airflow/providers/sftp/operators/sftp.py", line 164, in execute
    raise AirflowException(f"Error while transferring {file_msg}, error: {e}")
airflow.exceptions.AirflowException: Error while transferring from /tmp/hello-world to ., error: [Errno 2] No such file or directory: '/tmp/hello-world'
[2025-06-19T10:10:26.428+0000] {logging_mixin.py:190} INFO - Task instance in failure state
[2025-06-19T10:10:26.429+0000] {logging_mixin.py:190} INFO - Task start:2025-06-19 10:10:23.767487+00:00 end:2025-06-19 10:10:26.428056+00:00 duration:2.660569
[2025-06-19T10:10:26.429+0000] {logging_mixin.py:190} INFO - Task:<Task(SFTPOperator): scp_to_hpc> dag:<DAG: git_clone_and_scp_hello_world> dagrun:<DagRun git_clone_and_scp_hello_world @ 2025-06-19 10:10:16.769141+00:00: manual__2025-06-19T10:10:16.769141+00:00, state:running, queued_at: 2025-06-19 10:10:16.790630+00:00. externally triggered: True>
[2025-06-19T10:10:26.429+0000] {logging_mixin.py:190} INFO - Failure caused by Error while transferring from /tmp/hello-world to ., error: [Errno 2] No such file or directory: '/tmp/hello-world'
[2025-06-19T10:10:26.430+0000] {taskinstance.py:1226} INFO - Marking task as FAILED. dag_id=git_clone_and_scp_hello_world, task_id=scp_to_hpc, run_id=manual__2025-06-19T10:10:16.769141+00:00, execution_date=20250619T101016, start_date=20250619T101023, end_date=20250619T101026
[2025-06-19T10:10:26.459+0000] {taskinstance.py:341} INFO - ::group::Post task execution logs
[2025-06-19T10:10:26.460+0000] {standard_task_runner.py:124} ERROR - Failed to execute job 343 for task scp_to_hpc (Error while transferring from /tmp/hello-world to ., error: [Errno 2] No such file or directory: '/tmp/hello-world'; 1419)
Traceback (most recent call last):
  File "/home/airflow/.local/lib/python3.12/site-packages/airflow/providers/sftp/operators/sftp.py", line 161, in execute
    self.sftp_hook.store_file(_remote_filepath, _local_filepath, confirm=self.confirm)
  File "/home/airflow/.local/lib/python3.12/site-packages/airflow/providers/sftp/hooks/sftp.py", line 246, in store_file
    conn.put(local_full_path, remote_full_path, confirm=confirm)
  File "/home/airflow/.local/lib/python3.12/site-packages/paramiko/sftp_client.py", line 757, in put
    file_size = os.stat(localpath).st_size
                ^^^^^^^^^^^^^^^^^^
FileNotFoundError: [Errno 2] No such file or directory: '/tmp/hello-world'

During handling of the above exception, another exception occurred:

Traceback (most recent call last):
  File "/home/airflow/.local/lib/python3.12/site-packages/airflow/task/task_runner/standard_task_runner.py", line 117, in _start_by_fork
    ret = args.func(args, dag=self.dag)
          ^^^^^^^^^^^^^^^^^^^^^^^^^^^^^
  File "/home/airflow/.local/lib/python3.12/site-packages/airflow/cli/cli_config.py", line 49, in command
    return func(*args, **kwargs)
           ^^^^^^^^^^^^^^^^^^^^^
  File "/home/airflow/.local/lib/python3.12/site-packages/airflow/utils/cli.py", line 116, in wrapper
    return f(*args, **kwargs)
           ^^^^^^^^^^^^^^^^^^
  File "/home/airflow/.local/lib/python3.12/site-packages/airflow/cli/commands/task_command.py", line 483, in task_run
    task_return_code = _run_task_by_selected_method(args, _dag, ti)
                       ^^^^^^^^^^^^^^^^^^^^^^^^^^^^^^^^^^^^^^^^^^^^
  File "/home/airflow/.local/lib/python3.12/site-packages/airflow/cli/commands/task_command.py", line 256, in _run_task_by_selected_method
    return _run_raw_task(args, ti)
           ^^^^^^^^^^^^^^^^^^^^^^^
  File "/home/airflow/.local/lib/python3.12/site-packages/airflow/cli/commands/task_command.py", line 341, in _run_raw_task
    return ti._run_raw_task(
           ^^^^^^^^^^^^^^^^^
  File "/home/airflow/.local/lib/python3.12/site-packages/airflow/utils/session.py", line 97, in wrapper
    return func(*args, session=session, **kwargs)
           ^^^^^^^^^^^^^^^^^^^^^^^^^^^^^^^^^^^^^^
  File "/home/airflow/.local/lib/python3.12/site-packages/airflow/models/taskinstance.py", line 3006, in _run_raw_task
    return _run_raw_task(
           ^^^^^^^^^^^^^^
  File "/home/airflow/.local/lib/python3.12/site-packages/airflow/models/taskinstance.py", line 274, in _run_raw_task
    TaskInstance._execute_task_with_callbacks(
  File "/home/airflow/.local/lib/python3.12/site-packages/airflow/models/taskinstance.py", line 3161, in _execute_task_with_callbacks
    result = self._execute_task(context, task_orig)
             ^^^^^^^^^^^^^^^^^^^^^^^^^^^^^^^^^^^^^^
  File "/home/airflow/.local/lib/python3.12/site-packages/airflow/models/taskinstance.py", line 3185, in _execute_task
    return _execute_task(self, context, task_orig)
           ^^^^^^^^^^^^^^^^^^^^^^^^^^^^^^^^^^^^^^^
  File "/home/airflow/.local/lib/python3.12/site-packages/airflow/models/taskinstance.py", line 768, in _execute_task
    result = _execute_callable(context=context, **execute_callable_kwargs)
             ^^^^^^^^^^^^^^^^^^^^^^^^^^^^^^^^^^^^^^^^^^^^^^^^^^^^^^^^^^^^^
  File "/home/airflow/.local/lib/python3.12/site-packages/airflow/models/taskinstance.py", line 734, in _execute_callable
    return ExecutionCallableRunner(
           ^^^^^^^^^^^^^^^^^^^^^^^^
  File "/home/airflow/.local/lib/python3.12/site-packages/airflow/utils/operator_helpers.py", line 252, in run
    return self.func(*args, **kwargs)
           ^^^^^^^^^^^^^^^^^^^^^^^^^^
  File "/home/airflow/.local/lib/python3.12/site-packages/airflow/models/baseoperator.py", line 424, in wrapper
    return func(self, *args, **kwargs)
           ^^^^^^^^^^^^^^^^^^^^^^^^^^^
  File "/home/airflow/.local/lib/python3.12/site-packages/airflow/providers/sftp/operators/sftp.py", line 164, in execute
    raise AirflowException(f"Error while transferring {file_msg}, error: {e}")
airflow.exceptions.AirflowException: Error while transferring from /tmp/hello-world to ., error: [Errno 2] No such file or directory: '/tmp/hello-world'
[2025-06-19T10:10:26.493+0000] {local_task_job_runner.py:266} INFO - Task exited with return code 1
[2025-06-19T10:10:26.511+0000] {taskinstance.py:3901} INFO - 0 downstream tasks scheduled from follow-on schedule check
[2025-06-19T10:10:26.513+0000] {local_task_job_runner.py:245} INFO - ::endgroup::
